Workbook

Sheet Cover Sheet
C1: Rutgers University
C2: Introduction to Managerial Accounting
C3: Data Analysis Project
C4: Data Seed #1778
C5: Spring 2023
B7: Instructions and Background
B8: Class Section: | D8: 10
B9: Student Name(s): | D9: Hailey Gomez, and team
B10: Background: | D10: The Fashionable Leather Company manufactures two product lines (shoes and jackets) and operates in four regions (North, South, East, and West). The company buys direct materials and supplies only after receiving orders from customers, and therefore does not hold a material amount of inventory. The CFO asked you to analyze the company's performance for the year across a number of dimensions including by region, by product line, and by manufacturing cost. The raw job costing data was exported into Excel from the company's accounting system (the data is saved in the Data worksheet).
B11: Instructions: | D11: This workbook contains 3 worksheets: Cover Sheet, Additional Instructions, and Data. It is recommended that you add additional worksheets to perform your calculations, as necessary. However, only answers entered in the Cover Sheet will be graded. The Cover Sheet worksheet contains all of the questions as well as spaces for your answers. The cells on this worksheet are locked. You can only edit the gold colored cells. Column B lists the chapter that each question is most related to. However, there is overlap in many of the chapters. Column C lists the point value for each question. Many questions include either a hint or a check number. Make sure that your calculations match the check numbers. The gold colored answer cells are restricted to accept only certain number formats. For example, the answer for question 4 will only accept a whole number. If you try to enter 54.5 you will receive an error message. The Additional Instructions worksheet contains 1) a description of the dataset, 2) links to basic Excel video tutorials, and 3) additional instructions and hints on how to calculate and answer each of the questions. The majority of this project relies on using formulas to calculate new columns in a table of data and then using PivotTables to analyze the data. The Data worksheet contains the raw job costing data from the company's accounting system. Each row of the data table corresponds to one job. Each job can include orders for multiple quantities of a given product. A more detailed description of the data is included in the Additional Instructions tab. It is recommended that you calculate additional columns in the Data worksheet, as needed, before creating your pivot tables.
B17: Chapter | C17: Points | D17: Questions
B18: 2 | C18: 5 | D18: Question 1: | E18: What is the total direct material used (in dollars) for shoes?
D19: Answer: | E19: 675836.93
B21: 2 | C21: 5 | D21: Question 2: | E21: What is the total direct labor used (in dollars) in the South region?
D22: Answer: | E22: 271520.54
B24: 4 | C24: 5 | D24: Question 3: | E24: The budgeted manufacturing overhead rate is 25% of direct material dollars. (Hint: A job that incurs $100 of direct materials will be allocated $25 of manufacturing overhead.)
E25: What is the total manufacturing OH applied (in dollars)?
D26: Answer: | E26: 1094558.7
D27: Check: | E27: The total manufacturing OH applied in the North region was $324,840.
B29: 3 | C29: 5 | D29: Question 4: | E29: How many jackets were sold in the East region?
D30: Answer: | E30: 2787
B32: 2 | C32: 5 | D32: Question 5: | E32: Which product line generated the most revenue?
D33: Answer: | E33: Jacket
B35: 2 | C35: 5 | D35: Question 6: | E35: What is the total gross margin in each of the 4 regions?
D36: Answer: | E36: North | F36: South | G36: East | H36: West
E37: 296539.34 | F37: 267881.56 | G37: 166661.67 | H37: 268173.61
B39: 3 | C39: 5 | D39: Question 7: | E39: Which Job ID generated the smallest gross margin?
D40: Answer: | E40: 1321
B42: 4 | D42: Question 8: | E42: Assume the actual indirect manufactuing OH rate for the year was 25.51%. Manufacturing overhead is allocated using direct material dollars.
C43: 5 | D43: 8a. | E43: What was the actual total overhead incurred during the year?
D44: Answer: | E44: 1116887.7
C46: 2.5 | D46: 8b. | E46: What is the difference between actual total manufacturing overhead and the applied manufacturing overhead? (Hint: Actual total manufacturing overhead - total applied manufacturing overhead.)
D47: Answer: | E47: 22329
C49: 2.5 | D49: 8c. | E49: Was the manufacturing overhead over or underapplied?
D50: Answer: | E50: Under Applied
B52: 4 | C52: 10 | D52: Question 9: | E52: The budgeted period fixed costs for the year are $593,023, and the fixed portion of the budgeted total manufacturing overhead is $656,735.
E53: What are the total variable costs for the year? (Hint: The total variable costs is the total direct material costs + total direct labor costs + total manufacturing overhead applied - fixed portion of the budgeted manufacturing overhead.)
D54: Answer: | E54: 5756790.4
B56: 3 | C56: 12.5 | D56: Question 10: | E56: What is the average contribution margin per unit for shoes? Assume the fixed overhead costs are 60.00% of the applied overhead and there are no period variable costs. (Hint: Divide the total contribution margin for shoes by the total number of shoes sold.)
D57: Answer: | E57: 12.98
...

Sheet Additional Instructions
A1: ='Cover Sheet'!C1 -> Rutgers University
A2: ='Cover Sheet'!C2 -> Introduction to Managerial Accounting
A3: ='Cover Sheet'!C3 -> Data Analysis Project
A4: ='Cover Sheet'!C4 -> Data Seed #1778
A5: ='Cover Sheet'!C5 -> Spring 2023
A7: Description of Data
A8: Column Name | B8: Description
A9: Job ID | B9: A unique identification number for each job. This ID number cannot be repeated.
A10: Customer ID | B10: A unique identification number for each customer. A customer can be associated with multiple jobs.
A11: Region | B11: Identifies the region of the corresponding job. Possible values are North, South, East, and West.
A12: Product | B12: The product produced and sold for the job. Possible values are shoes or jackets.
A13: Units Produced and Sold | B13: The number of shoes or jackets produced and sold for the job. Note: An order for 2 shoes is for 2 pairs of shoes.
A14: Cost per Foot of Leather | B14: The direct material cost per foot of leather. (e.g., the price of 1 foot of leather.)
A15: Feet of Leather per Unit Produced | B15: The number of feet of leather used per unit of output. (e.g. 12 feet of leather to produce 1 jacket).
A16: Direct Labor Cost per Hour | B16: The hourly wage rate for manufacturing employees. (e.g., Employee is paid $31 /hour).
A17: Direct Labor Hours Per Unit Produced | B17: The number of direct labor hours used to produce 1 unit of output. (e.g., The employee uses 1.05 hours to produce 1 jacket.)
A18: Sales Price per Unit | B18: The sales price per unit. (e.g., Each jacket is sold for $383.)
A20: Excel References
A21: Excel Basics | B21: Video Link
A22: Excel enter a basic formula. | B22: https://www.youtube.com/watch?v=xKiUl2gQEwo
A23: How to create a pivot table. | B23: https://www.youtube.com/watch?v=gpTVQxv9vi0
A24: How to sort a pivot table. | B24: https://www.youtube.com/watch?v=iQmsuCxTjKs
A25: How to filter a pivot table. | B25: https://www.youtube.com/watch?v=2U-pJtkQK8Y
A26: Excel XLOOKUP function. | B26: https://www.youtube.com/watch?v=-10hVtmTmG4
A28: Additional Instructions
A29: Question # | B29: Additional Information
A30: General | B30: Remember that expenses are subtracted from revenue when calculating gross margin, contribution margin, etc. Therefore, it may be easier to represent the columns which contain expenses as negative numbers.
A31: General | B31: The majority of this project relies on using basic Excel formulas and PivotTables. The links included above will be helpful if you are unfamiliar with Excel.
A32: Question 8b | B32: Remember the applied manufacturing overhead was calculated as part of Question 3.
A33: Question 10 | B33: Remember the contribution margin equals revenue - variable costs.
A34: Question 11 | B34: The total fixed costs are reported in Question 9. There are no variable period costs.
A35: Question 12 | B35: The total direct material price variance and the total direct material efficiency variance is the sum of each job's variances. A simple way to calculate the answer is to calculate the direct material price variance and the direct material efficiency variance for each job. Then, use a PivotTable to sum all of the variances calculated for each job. This approach requires that you include the direct material standard price and standard quantities for each job within the Data worksheet. You can do this by creating a lookup table (use the table at the right). Fill the gold cells of the lookup table with the standard price and quantities listed in the Cover Sheet worksheet and use the XLOOKUP function in the Data worksheet to create the two new columns. | D35: Standard Price and Quantity Lookup Table
D36: Product | E36: Standard Price | F36: Standard Quantity
D37: JACKET
D38: SHOES

Sheet Data
A1: Job ID | B1: Customer ID | C1: Region | D1: Product | E1: Units Produced and Sold | F1: Cost per Foot of Leather | G1: Feet of Leather per Unit Produced | H1: Direct Labor Cost per Hour | I1: Direct Labor Hours Per Unit Produced | J1: Sales Price per Unit | K1: Total Revenues | L1: Shoe Revenue | M1: Direct Materials Shoes | N1: Applied OH Shoes | O1: Direct Materials Cost | P1: Manf. OH Applied | Q1: Actual Overhead Incurred | R1: Direct Labor Costs | S1: Revenues | U1: DM Jackets | V1: Actual | W1: Middle | X1: Flex | Y1: Static
A2: 132 | B2: 1247 | C2: South | D2: JACKET | E2: 14 | F2: 19.43 | G2: 11.24 | H2: 30.9 | I2: 1.05 | J2: 363.47 | K2: =E2*J2 -> 5088.58 | L2: =IF(D2="SHOES",E2*J2,0) -> 0 | M2: =IF(D2="SHOES",O2,0) -> 0 | N2: =IF(D2="SHOES",P2,0) -> 0 | O2: =PRODUCT(E2,G2,F2) -> 3057.5048 | P2: =PRODUCT(O2,0.25) -> 764.3762 | Q2: =PRODUCT(O2,0.2551) -> 779.96947 | R2: =PRODUCT(E2,I2,H2) -> 454.23 | S2: =PRODUCT(J2,E2) -> 5088.58 | U2: output | V2: =SUMIF($D$2:$D$1703,"JACKET",$E$2:$E$1703) -> 17125 | X2: =SUMIF($D$2:$D$1703,"JACKET",$E$2:$E$1703) -> 17125
A3: 133 | B3: 1247 | C3: South | D3: JACKET | E3: 13 | F3: 18.67 | G3: 10.83 | H3: 31.65 | I3: 0.95 | J3: 336.55 | K3: =E3*J3 -> 4375.15 | L3: =IF(D3="SHOES",E3*J3,0) -> 0 | M3: =IF(D3="SHOES",O3,0) -> 0 | N3: =IF(D3="SHOES",P3,0) -> 0 | O3: =PRODUCT(E3,G3,F3) -> 2628.5493 | P3: =PRODUCT(O3,0.25) -> 657.13733 | Q3: =PRODUCT(O3,0.2551) -> 670.54293 | R3: =PRODUCT(E3,I3,H3) -> 390.8775 | S3: =PRODUCT(J3,E3) -> 4375.15 | U3: input/output | V3: =AVERAGEIF($D$2:$D$1703,"JACKET",$G$2:$G$1703) -> 11.04893 | X3: 11.04 | Y3: 11.04
A4: 134 | B4: 1247 | C4: South | D4: JACKET | E4: 17 | F4: 19.38 | G4: 9.95 | H4: 32.42 | I4: 1.03 | J4: 326.57 | K4: =E4*J4 -> 5551.69 | L4: =IF(D4="SHOES",E4*J4,0) -> 0 | M4: =IF(D4="SHOES",O4,0) -> 0 | N4: =IF(D4="SHOES",P4,0) -> 0 | O4: =PRODUCT(E4,G4,F4) -> 3278.127 | P4: =PRODUCT(O4,0.25) -> 819.53175 | Q4: =PRODUCT(O4,0.2551) -> 836.2502 | R4: =PRODUCT(E4,I4,H4) -> 567.6742 | S4: =PRODUCT(J4,E4) -> 5551.69 | U4: input | V4: =V3*V2 -> 189212.92 | W4: =V3*V2 -> 189212.92 | X4: =X3*X2 -> 189060
A5: 135 | B5: 1247 | C5: South | D5: SHOES | E5: 27 | F5: 14.68 | G5: 2.8 | H5: 32.17 | I5: 0.79 | J5: 84.47 | K5: =E5*J5 -> 2280.69 | L5: =IF(D5="SHOES",E5*J5,0) -> 2280.69 | M5: =IF(D5="SHOES",O5,0) -> 1109.808 | N5: =IF(D5="SHOES",P5,0) -> 277.452 | O5: =PRODUCT(E5,G5,F5) -> 1109.808 | P5: =PRODUCT(O5,0.25) -> 277.452 | Q5: =PRODUCT(O5,0.2551) -> 283.11202 | R5: =PRODUCT(E5,I5,H5) -> 686.1861 | S5: =PRODUCT(J5,E5) -> 2280.69 | U5: rate | V5: =V6/V4 -> 19.567363 | W5: 19.6 | X5: 19.6 | Y5: 19.6
A6: 136 | B6: 1247 | C6: South | D6: SHOES | E6: 9 | F6: 15.87 | G6: 2.62 | H6: 31.82 | I6: 0.79 | J6: 84.82 | K6: =E6*J6 -> 763.38 | L6: =IF(D6="SHOES",E6*J6,0) -> 763.38 | M6: =IF(D6="SHOES",O6,0) -> 374.2146 | N6: =IF(D6="SHOES",P6,0) -> 93.55365 | O6: =PRODUCT(E6,G6,F6) -> 374.2146 | P6: =PRODUCT(O6,0.25) -> 93.55365 | Q6: =PRODUCT(O6,0.2551) -> 95.462144 | R6: =PRODUCT(E6,I6,H6) -> 226.2402 | S6: =PRODUCT(J6,E6) -> 763.38 | U6: TC | V6: =SUMIF(D2:D1703,"JACKET",O2:O1703) -> 3702397.9 | W6: =W5*W4 -> 3708573.3 | X6: =X5*X4 -> 3705576
A7: 137 | B7: 1247 | C7: South | D7: JACKET | E7: 13 | F7: 20.17 | G7: 9.99 | H7: 23.94 | I7: 0.97 | J7: 327.36 | K7: =E7*J7 -> 4255.68 | L7: =IF(D7="SHOES",E7*J7,0) -> 0 | M7: =IF(D7="SHOES",O7,0) -> 0 | N7: =IF(D7="SHOES",P7,0) -> 0 | O7: =PRODUCT(E7,G7,F7) -> 2619.4779 | P7: =PRODUCT(O7,0.25) -> 654.86948 | Q7: =PRODUCT(O7,0.2551) -> 668.22881 | R7: =PRODUCT(E7,I7,H7) -> 301.8834 | S7: =PRODUCT(J7,E7) -> 4255.68
A8: 138 | B8: 1247 | C8: South | D8: SHOES | E8: 24 | F8: 15.54 | G8: 2.99 | H8: 24.72 | I8: 0.79 | J8: 85.37 | K8: =E8*J8 -> 2048.88 | L8: =IF(D8="SHOES",E8*J8,0) -> 2048.88 | M8: =IF(D8="SHOES",O8,0) -> 1115.1504 | N8: =IF(D8="SHOES",P8,0) -> 278.7876 | O8: =PRODUCT(E8,G8,F8) -> 1115.1504 | P8: =PRODUCT(O8,0.25) -> 278.7876 | Q8: =PRODUCT(O8,0.2551) -> 284.47487 | R8: =PRODUCT(E8,I8,H8) -> 468.6912 | S8: =PRODUCT(J8,E8) -> 2048.88 | V8: =W6-V6 -> 6175.3456 | X8: =W6-X6 -> 2997.2888
A9: 139 | B9: 1247 | C9: South | D9: JACKET | E9: 13 | F9: 22.01 | G9: 11.09 | H9: 26.18 | I9: 0.92 | J9: 391.75 | K9: =E9*J9 -> 5092.75 | L9: =IF(D9="SHOES",E9*J9,0) -> 0 | M9: =IF(D9="SHOES",O9,0) -> 0 | N9: =IF(D9="SHOES",P9,0) -> 0 | O9: =PRODUCT(E9,G9,F9) -> 3173.1817 | P9: =PRODUCT(O9,0.25) -> 793.29543 | Q9: =PRODUCT(O9,0.2551) -> 809.47865 | R9: =PRODUCT(E9,I9,H9) -> 313.1128 | S9: =PRODUCT(J9,E9) -> 5092.75 | V9: Price Var (F) | X9: Efficency Var (U)
A10: 140 | B10: 1248 | C10: South | D10: JACKET | E10: 19 | F10: 20 | G10: 10.26 | H10: 29.36 | I10: 1.02 | J10: 340.87 | K10: =E10*J10 -> 6476.53 | L10: =IF(D10="SHOES",E10*J10,0) -> 0 | M10: =IF(D10="SHOES",O10,0) -> 0 | N10: =IF(D10="SHOES",P10,0) -> 0 | O10: =PRODUCT(E10,G10,F10) -> 3898.8 | P10: =PRODUCT(O10,0.25) -> 974.7 | Q10: =PRODUCT(O10,0.2551) -> 994.58388 | R10: =PRODUCT(E10,I10,H10) -> 568.9968 | S10: =PRODUCT(J10,E10) -> 6476.53
A11: 141 | B11: 1248 | C11: South | D11: SHOES | E11: 16 | F11: 15.57 | G11: 2.98 | H11: 30.63 | I11: 0.78 | J11: 90.08 | K11: =E11*J11 -> 1441.28 | L11: =IF(D11="SHOES",E11*J11,0) -> 1441.28 | M11: =IF(D11="SHOES",O11,0) -> 742.3776 | N11: =IF(D11="SHOES",P11,0) -> 185.5944 | O11: =PRODUCT(E11,G11,F11) -> 742.3776 | P11: =PRODUCT(O11,0.25) -> 185.5944 | Q11: =PRODUCT(O11,0.2551) -> 189.38053 | R11: =PRODUCT(E11,I11,H11) -> 382.2624 | S11: =PRODUCT(J11,E11) -> 1441.28 | U11: DM Shoes | V11: Actual | W11: Middle | X11: Flex | Y11: Static
A12: 142 | B12: 1248 | C12: South | D12: SHOES | E12: 16 | F12: 15.25 | G12: 2.86 | H12: 36.63 | I12: 0.81 | J12: 92.61 | K12: =E12*J12 -> 1481.76 | L12: =IF(D12="SHOES",E12*J12,0) -> 1481.76 | M12: =IF(D12="SHOES",O12,0) -> 697.84 | N12: =IF(D12="SHOES",P12,0) -> 174.46 | O12: =PRODUCT(E12,G12,F12) -> 697.84 | P12: =PRODUCT(O12,0.25) -> 174.46 | Q12: =PRODUCT(O12,0.2551) -> 178.01898 | R12: =PRODUCT(E12,I12,H12) -> 474.7248 | S12: =PRODUCT(J12,E12) -> 1481.76 | U12: output | V12: =SUMIF($D$2:$D$1703,"SHOES",$E$2:$E$1703) -> 16037 | X12: =SUMIF($D$2:$D$1703,"SHOES",$E$2:$E$1703) -> 16037
A13: 143 | B13: 1248 | C13: South | D13: JACKET | E13: 17 | F13: 17.42 | G13: 12.34 | H13: 31.39 | I13: 1.01 | J13: 357.49 | K13: =E13*J13 -> 6077.33 | L13: =IF(D13="SHOES",E13*J13,0) -> 0 | M13: =IF(D13="SHOES",O13,0) -> 0 | N13: =IF(D13="SHOES",P13,0) -> 0 | O13: =PRODUCT(E13,G13,F13) -> 3654.3676 | P13: =PRODUCT(O13,0.25) -> 913.5919 | Q13: =PRODUCT(O13,0.2551) -> 932.22917 | R13: =PRODUCT(E13,I13,H13) -> 538.9663 | S13: =PRODUCT(J13,E13) -> 6077.33 | U13: input/output | V13: =AVERAGEIF($D$2:$D$1703,"SHOES",$G$2:$G$1703) -> 2.8693878 | X13: 2.87 | Y13: 2.87
A14: 144 | B14: 1248 | C14: South | D14: JACKET | E14: 13 | F14: 18.85 | G14: 11.52 | H14: 31.37 | I14: 0.98 | J14: 359.6 | K14: =E14*J14 -> 4674.8 | L14: =IF(D14="SHOES",E14*J14,0) -> 0 | M14: =IF(D14="SHOES",O14,0) -> 0 | N14: =IF(D14="SHOES",P14,0) -> 0 | O14: =PRODUCT(E14,G14,F14) -> 2822.976 | P14: =PRODUCT(O14,0.25) -> 705.744 | Q14: =PRODUCT(O14,0.2551) -> 720.14118 | R14: =PRODUCT(E14,I14,H14) -> 399.6538 | S14: =PRODUCT(J14,E14) -> 4674.8 | U14: input | V14: =V13*V12 -> 46016.371 | W14: =V13*V12 -> 46016.371 | X14: =X13*X12 -> 46026.19
A15: 145 | B15: 1248 | C15: South | D15: SHOES | E15: 12 | F15: 16.64 | G15: 2.9 | H15: 30.23 | I15: 0.78 | J15: 92.29 | K15: =E15*J15 -> 1107.48 | L15: =IF(D15="SHOES",E15*J15,0) -> 1107.48 | M15: =IF(D15="SHOES",O15,0) -> 579.072 | N15: =IF(D15="SHOES",P15,0) -> 144.768 | O15: =PRODUCT(E15,G15,F15) -> 579.072 | P15: =PRODUCT(O15,0.25) -> 144.768 | Q15: =PRODUCT(O15,0.2551) -> 147.72127 | R15: =PRODUCT(E15,I15,H15) -> 282.9528 | S15: =PRODUCT(J15,E15) -> 1107.48 | U15: rate | V15: =V16/V14 -> 14.68688 | W15: 14.85 | X15: 14.85 | Y15: 14.85
A16: 146 | B16: 1248 | C16: South | D16: JACKET | E16: 11 | F16: 19.45 | G16: 12 | H16: 32.09 | I16: 1.07 | J16: 388.04 | K16: =E16*J16 -> 4268.44 | L16: =IF(D16="SHOES",E16*J16,0) -> 0 | M16: =IF(D16="SHOES",O16,0) -> 0 | N16: =IF(D16="SHOES",P16,0) -> 0 | O16: =PRODUCT(E16,G16,F16) -> 2567.4 | P16: =PRODUCT(O16,0.25) -> 641.85 | Q16: =PRODUCT(O16,0.2551) -> 654.94374 | R16: =PRODUCT(E16,I16,H16) -> 377.6993 | S16: =PRODUCT(J16,E16) -> 4268.44 | U16: TC | V16: =SUMIF(D2:D1703,"SHOES",O2:O1703) -> 675836.93 | W16: =W15*W14 -> 683343.12 | X16: =X15*X14 -> 683488.92
A17: 147 | B17: 1248 | C17: South | D17: JACKET | E17: 18 | F17: 19.2 | G17: 11.07 | H17: 29.03 | I17: 0.91 | J17: 347.6 | K17: =E17*J17 -> 6256.8 | L17: =IF(D17="SHOES",E17*J17,0) -> 0 | M17: =IF(D17="SHOES",O17,0) -> 0 | N17: =IF(D17="SHOES",P17,0) -> 0 | O17: =PRODUCT(E17,G17,F17) -> 3825.792 | P17: =PRODUCT(O17,0.25) -> 956.448 | Q17: =PRODUCT(O17,0.2551) -> 975.95954 | R17: =PRODUCT(E17,I17,H17) -> 475.5114 | S17: =PRODUCT(J17,E17) -> 6256.8
A18: 148 | B18: 1248 | C18: South | D18: JACKET | E18: 13 | F18: 20.01 | G18: 11.07 | H18: 23.57 | I18: 1.06 | J18: 359.23 | K18: =E18*J18 -> 4669.99 | L18: =IF(D18="SHOES",E18*J18,0) -> 0 | M18: =IF(D18="SHOES",O18,0) -> 0 | N18: =IF(D18="SHOES",P18,0) -> 0 | O18: =PRODUCT(E18,G18,F18) -> 2879.6391 | P18: =PRODUCT(O18,0.25) -> 719.90978 | Q18: =PRODUCT(O18,0.2551) -> 734.59593 | R18: =PRODUCT(E18,I18,H18) -> 324.7946 | S18: =PRODUCT(J18,E18) -> 4669.99 | V18: =W16-V16 -> 7506.188 | X18: =X16-W16 -> 145.80579
A19: 149 | B19: 1249 | C19: West | D19: JACKET | E19: 13 | F19: 20.85 | G19: 11.75 | H19: 31.02 | I19: 1.02 | J19: 402.07 | K19: =E19*J19 -> 5226.91 | L19: =IF(D19="SHOES",E19*J19,0) -> 0 | M19: =IF(D19="SHOES",O19,0) -> 0 | N19: =IF(D19="SHOES",P19,0) -> 0 | O19: =PRODUCT(E19,G19,F19) -> 3184.8375 | P19: =PRODUCT(O19,0.25) -> 796.20938 | Q19: =PRODUCT(O19,0.2551) -> 812.45205 | R19: =PRODUCT(E19,I19,H19) -> 411.3252 | S19: =PRODUCT(J19,E19) -> 5226.91 | V19: Price Var (F) | X19: Efficency Var (F)
A20: 150 | B20: 1249 | C20: West | D20: SHOES | E20: 20 | F20: 14.91 | G20: 3.01 | H20: 28.11 | I20: 0.8 | J20: 77.02 | K20: =E20*J20 -> 1540.4 | L20: =IF(D20="SHOES",E20*J20,0) -> 1540.4 | M20: =IF(D20="SHOES",O20,0) -> 897.582 | N20: =IF(D20="SHOES",P20,0) -> 224.3955 | O20: =PRODUCT(E20,G20,F20) -> 897.582 | P20: =PRODUCT(O20,0.25) -> 224.3955 | Q20: =PRODUCT(O20,0.2551) -> 228.97317 | R20: =PRODUCT(E20,I20,H20) -> 449.76 | S20: =PRODUCT(J20,E20) -> 1540.4
A21: 151 | B21: 1249 | C21: West | D21: SHOES | E21: 19 | F21: 15.52 | G21: 2.98 | H21: 27.87 | I21: 0.8 | J21: 88.12 | K21: =E21*J21 -> 1674.28 | L21: =IF(D21="SHOES",E21*J21,0) -> 1674.28 | M21: =IF(D21="SHOES",O21,0) -> 878.7424 | N21: =IF(D21="SHOES",P21,0) -> 219.6856 | O21: =PRODUCT(E21,G21,F21) -> 878.7424 | P21: =PRODUCT(O21,0.25) -> 219.6856 | Q21: =PRODUCT(O21,0.2551) -> 224.16719 | R21: =PRODUCT(E21,I21,H21) -> 423.624 | S21: =PRODUCT(J21,E21) -> 1674.28 | X21: =X8-X18 -> 2851.4831
A22: 152 | B22: 1249 | C22: West | D22: JACKET | E22: 9 | F22: 18.95 | G22: 11.13 | H22: 26.59 | I22: 0.93 | J22: 343.16 | K22: =E22*J22 -> 3088.44 | L22: =IF(D22="SHOES",E22*J22,0) -> 0 | M22: =IF(D22="SHOES",O22,0) -> 0 | N22: =IF(D22="SHOES",P22,0) -> 0 | O22: =PRODUCT(E22,G22,F22) -> 1898.2215 | P22: =PRODUCT(O22,0.25) -> 474.55537 | Q22: =PRODUCT(O22,0.2551) -> 484.2363 | R22: =PRODUCT(E22,I22,H22) -> 222.5583 | S22: =PRODUCT(J22,E22) -> 3088.44 | X22: total efficency Var (U)
A23: 153 | B23: 1249 | C23: West | D23: JACKET | E23: 18 | F23: 19.56 | G23: 11.54 | H23: 28.55 | I23: 0.98 | J23: 369.06 | K23: =E23*J23 -> 6643.08 | L23: =IF(D23="SHOES",E23*J23,0) -> 0 | M23: =IF(D23="SHOES",O23,0) -> 0 | N23: =IF(D23="SHOES",P23,0) -> 0 | O23: =PRODUCT(E23,G23,F23) -> 4063.0032 | P23: =PRODUCT(O23,0.25) -> 1015.7508 | Q23: =PRODUCT(O23,0.2551) -> 1036.4721 | R23: =PRODUCT(E23,I23,H23) -> 503.622 | S23: =PRODUCT(J23,E23) -> 6643.08 | U23: Problem 4
A24: 154 | B24: 1249 | C24: West | D24: SHOES | E24: 9 | F24: 15.71 | G24: 2.87 | H24: 34.54 | I24: 0.79 | J24: 92.01 | K24: =E24*J24 -> 828.09 | L24: =IF(D24="SHOES",E24*J24,0) -> 828.09 | M24: =IF(D24="SHOES",O24,0) -> 405.7893 | N24: =IF(D24="SHOES",P24,0) -> 101.44733 | O24: =PRODUCT(E24,G24,F24) -> 405.7893 | P24: =PRODUCT(O24,0.25) -> 101.44733 | Q24: =PRODUCT(O24,0.2551) -> 103.51685 | R24: =PRODUCT(E24,I24,H24) -> 245.5794 | S24: =PRODUCT(J24,E24) -> 828.09 | U24: # of Jackets Sold in East Region
A25: 155 | B25: 1249 | C25: West | D25: JACKET | E25: 56 | F25: 19.86 | G25: 10.96 | H25: 31.65 | I25: 1.1 | J25: 365.21 | K25: =E25*J25 -> 20451.76 | L25: =IF(D25="SHOES",E25*J25,0) -> 0 | M25: =IF(D25="SHOES",O25,0) -> 0 | N25: =IF(D25="SHOES",P25,0) -> 0 | O25: =PRODUCT(E25,G25,F25) -> 12189.274 | P25: =PRODUCT(O25,0.25) -> 3047.3184 | Q25: =PRODUCT(O25,0.2551) -> 3109.4837 | R25: =PRODUCT(E25,I25,H25) -> 1949.64 | S25: =PRODUCT(J25,E25) -> 20451.76 | V25: =COUNTIFS(C2:C1703,"East",D2:D1703,"Jacket") -> 156
A26: 156 | B26: 1249 | C26: West | D26: SHOES | E26: 22 | F26: 17.2 | G26: 2.84 | H26: 34.12 | I26: 0.81 | J26: 97.57 | K26: =E26*J26 -> 2146.54 | L26: =IF(D26="SHOES",E26*J26,0) -> 2146.54 | M26: =IF(D26="SHOES",O26,0) -> 1074.656 | N26: =IF(D26="SHOES",P26,0) -> 268.664 | O26: =PRODUCT(E26,G26,F26) -> 1074.656 | P26: =PRODUCT(O26,0.25) -> 268.664 | Q26: =PRODUCT(O26,0.2551) -> 274.14475 | R26: =PRODUCT(E26,I26,H26) -> 608.0184 | S26: =PRODUCT(J26,E26) -> 2146.54
A27: 157 | B27: 1249 | C27: West | D27: SHOES | E27: 18 | F27: 14.24 | G27: 2.96 | H27: 29.12 | I27: 0.78 | J27: 82.94 | K27: =E27*J27 -> 1492.92 | L27: =IF(D27="SHOES",E27*J27,0) -> 1492.92 | M27: =IF(D27="SHOES",O27,0) -> 758.7072 | N27: =IF(D27="SHOES",P27,0) -> 189.6768 | O27: =PRODUCT(E27,G27,F27) -> 758.7072 | P27: =PRODUCT(O27,0.25) -> 189.6768 | Q27: =PRODUCT(O27,0.2551) -> 193.54621 | R27: =PRODUCT(E27,I27,H27) -> 408.8448 | S27: =PRODUCT(J27,E27) -> 1492.92
A28: 158 | B28: 1249 | C28: West | D28: JACKET | E28: 15 | F28: 19.39 | G28: 11.09 | H28: 32.79 | I28: 0.93 | J28: 356.15 | K28: =E28*J28 -> 5342.25 | L28: =IF(D28="SHOES",E28*J28,0) -> 0 | M28: =IF(D28="SHOES",O28,0) -> 0 | N28: =IF(D28="SHOES",P28,0) -> 0 | O28: =PRODUCT(E28,G28,F28) -> 3225.5265 | P28: =PRODUCT(O28,0.25) -> 806.38162 | Q28: =PRODUCT(O28,0.2551) -> 822.83181 | R28: =PRODUCT(E28,I28,H28) -> 457.4205 | S28: =PRODUCT(J28,E28) -> 5342.25
A29: 159 | B29: 1250 | C29: South | D29: JACKET | E29: 13 | F29: 19.22 | G29: 10.93 | H29: 32.37 | I29: 0.86 | J29: 345.61 | K29: =E29*J29 -> 4492.93 | L29: =IF(D29="SHOES",E29*J29,0) -> 0 | M29: =IF(D29="SHOES",O29,0) -> 0 | N29: =IF(D29="SHOES",P29,0) -> 0 | O29: =PRODUCT(E29,G29,F29) -> 2730.9698 | P29: =PRODUCT(O29,0.25) -> 682.74245 | Q29: =PRODUCT(O29,0.2551) -> 696.6704 | R29: =PRODUCT(E29,I29,H29) -> 361.8966 | S29: =PRODUCT(J29,E29) -> 4492.93
A30: 160 | B30: 1250 | C30: South | D30: SHOES | E30: 15 | F30: 13.45 | G30: 3.04 | H30: 31.58 | I30: 0.78 | J30: 83.32 | K30: =E30*J30 -> 1249.8 | L30: =IF(D30="SHOES",E30*J30,0) -> 1249.8 | M30: =IF(D30="SHOES",O30,0) -> 613.32 | N30: =IF(D30="SHOES",P30,0) -> 153.33 | O30: =PRODUCT(E30,G30,F30) -> 613.32 | P30: =PRODUCT(O30,0.25) -> 153.33 | Q30: =PRODUCT(O30,0.2551) -> 156.45793 | R30: =PRODUCT(E30,I30,H30) -> 369.486 | S30: =PRODUCT(J30,E30) -> 1249.8
A31: 161 | B31: 1250 | C31: South | D31: JACKET | E31: 7 | F31: 18.69 | G31: 10.79 | H31: 34.21 | I31: 1.03 | J31: 341.91 | K31: =E31*J31 -> 2393.37 | L31: =IF(D31="SHOES",E31*J31,0) -> 0 | M31: =IF(D31="SHOES",O31,0) -> 0 | N31: =IF(D31="SHOES",P31,0) -> 0 | O31: =PRODUCT(E31,G31,F31) -> 1411.6557 | P31: =PRODUCT(O31,0.25) -> 352.91393 | Q31: =PRODUCT(O31,0.2551) -> 360.11337 | R31: =PRODUCT(E31,I31,H31) -> 246.6541 | S31: =PRODUCT(J31,E31) -> 2393.37
A32: 162 | B32: 1250 | C32: South | D32: SHOES | E32: 12 | F32: 15.4 | G32: 2.82 | H32: 32.44 | I32: 0.79 | J32: 87.9 | K32: =E32*J32 -> 1054.8 | L32: =IF(D32="SHOES",E32*J32,0) -> 1054.8 | M32: =IF(D32="SHOES",O32,0) -> 521.136 | N32: =IF(D32="SHOES",P32,0) -> 130.284 | O32: =PRODUCT(E32,G32,F32) -> 521.136 | P32: =PRODUCT(O32,0.25) -> 130.284 | Q32: =PRODUCT(O32,0.2551) -> 132.94179 | R32: =PRODUCT(E32,I32,H32) -> 307.5312 | S32: =PRODUCT(J32,E32) -> 1054.8
A33: 163 | B33: 1250 | C33: South | D33: JACKET | E33: 25 | F33: 19.54 | G33: 10.43 | H33: 35.8 | I33: 0.97 | J33: 344.48 | K33: =E33*J33 -> 8612 | L33: =IF(D33="SHOES",E33*J33,0) -> 0 | M33: =IF(D33="SHOES",O33,0) -> 0 | N33: =IF(D33="SHOES",P33,0) -> 0 | O33: =PRODUCT(E33,G33,F33) -> 5095.055 | P33: =PRODUCT(O33,0.25) -> 1273.7637 | Q33: =PRODUCT(O33,0.2551) -> 1299.7485 | R33: =PRODUCT(E33,I33,H33) -> 868.15 | S33: =PRODUCT(J33,E33) -> 8612
A34: 164 | B34: 1250 | C34: South | D34: SHOES | E34: 17 | F34: 13.65 | G34: 3.05 | H34: 32.86 | I34: 0.79 | J34: 85.8 | K34: =E34*J34 -> 1458.6 | L34: =IF(D34="SHOES",E34*J34,0) -> 1458.6 | M34: =IF(D34="SHOES",O34,0) -> 707.7525 | N34: =IF(D34="SHOES",P34,0) -> 176.93812 | O34: =PRODUCT(E34,G34,F34) -> 707.7525 | P34: =PRODUCT(O34,0.25) -> 176.93812 | Q34: =PRODUCT(O34,0.2551) -> 180.54766 | R34: =PRODUCT(E34,I34,H34) -> 441.3098 | S34: =PRODUCT(J34,E34) -> 1458.6
A35: 165 | B35: 1250 | C35: South | D35: JACKET | E35: 19 | F35: 20.1 | G35: 10.47 | H35: 31.54 | I35: 1.05 | J35: 352.45 | K35: =E35*J35 -> 6696.55 | L35: =IF(D35="SHOES",E35*J35,0) -> 0 | M35: =IF(D35="SHOES",O35,0) -> 0 | N35: =IF(D35="SHOES",P35,0) -> 0 | O35: =PRODUCT(E35,G35,F35) -> 3998.493 | P35: =PRODUCT(O35,0.25) -> 999.62325 | Q35: =PRODUCT(O35,0.2551) -> 1020.0156 | R35: =PRODUCT(E35,I35,H35) -> 629.223 | S35: =PRODUCT(J35,E35) -> 6696.55
A36: 166 | B36: 1250 | C36: South | D36: SHOES | E36: 19 | F36: 14.21 | G36: 2.65 | H36: 26.27 | I36: 0.8 | J36: 66.72 | K36: =E36*J36 -> 1267.68 | L36: =IF(D36="SHOES",E36*J36,0) -> 1267.68 | M36: =IF(D36="SHOES",O36,0) -> 715.4735 | N36: =IF(D36="SHOES",P36,0) -> 178.86838 | O36: =PRODUCT(E36,G36,F36) -> 715.4735 | P36: =PRODUCT(O36,0.25) -> 178.86838 | Q36: =PRODUCT(O36,0.2551) -> 182.51729 | R36: =PRODUCT(E36,I36,H36) -> 399.304 | S36: =PRODUCT(J36,E36) -> 1267.68
A37: 167 | B37: 1250 | C37: South | D37: JACKET | E37: 15 | F37: 21 | G37: 10.66 | H37: 33.51 | I37: 1 | J37: 372.87 | K37: =E37*J37 -> 5593.05 | L37: =IF(D37="SHOES",E37*J37,0) -> 0 | M37: =IF(D37="SHOES",O37,0) -> 0 | N37: =IF(D37="SHOES",P37,0) -> 0 | O37: =PRODUCT(E37,G37,F37) -> 3357.9 | P37: =PRODUCT(O37,0.25) -> 839.475 | Q37: =PRODUCT(O37,0.2551) -> 856.60029 | R37: =PRODUCT(E37,I37,H37) -> 502.65 | S37: =PRODUCT(J37,E37) -> 5593.05
... A1703: 1833 | B1703: 1391 | C1703: East | D1703: SHOES | E1703: 14 | F1703: 15.62 | G1703: 2.85 | H1703: 32.71 | I1703: 0.78 | J1703: 89.28 | K1703: =E1703*J1703 -> 1249.92 | L1703: =IF(D1703="SHOES",E1703*J1703,0) -> 1249.92 | M1703: =IF(D1703="SHOES",O1703,0) -> 623.238 | N1703: =IF(D1703="SHOES",P1703,0) -> 155.8095 | O1703: =PRODUCT(E1703,G1703,F1703) -> 623.238 | P1703: =PRODUCT(O1703,0.25) -> 155.8095 | Q1703: =PRODUCT(O1703,0.2551) -> 158.98801 | R1703: =PRODUCT(E1703,I1703,H1703) -> 357.1932 | S1703: =PRODUCT(J1703,E1703) -> 1249.92
H1705: Problem 10 Workspace | O1705: Total Direct Materials Cost | P1705: Manf. OH applied sum | Q1705: Actual total OH incurred | R1705: Total direct labor costs
I1706: Total Shoe Revenues | J1706: =SUM(L2:L1703) -> 1347317 | O1706: =SUM(O2:O1703) -> 4378234.9 | P1706: =SUM(P2:P1703) -> 1094558.7 | Q1706: =SUM(Q2:Q1703) -> 1116887.7 | R1706: =SUM(R2:R1703) -> 940731.84
...

Sheet Pivot Table
